<?xml version="1.0" ?>
<!-- =================================================================================== -->
<!-- |    This document was autogenerated by xacro from thorvald_ii.xacro              | -->
<!-- |    EDITING THIS FILE BY HAND IS NOT RECOMMENDED                                 | -->
<!-- =================================================================================== -->
<robot name="thorvald_ii" xmlns:xacro="http://www.ros.org/wiki/xacro">
  <link name="front_frame">
  </link>
  <link name="base_link">
  </link>
  <link name="front_link">
      <inertial>
         <mass value="3.57593" />
         <inertia  ixx="9.10834154273" ixy="1.58213307656"  ixz="2.41894531959"  iyy="7.61461127751"  iyz="3.78869385449"  izz="3.51520282177" />
       </inertial>
    <visual>
      <geometry>
        <box size="0.04 1.5 0.19"/>
      </geometry>
      <material name="white">
        <color rgba="1 1 1 1"/>
      </material>
    </visual>
    <collision>
      <geometry>
        <box size="0.04 1.5 0.19"/>
      </geometry>
    </collision>
  </link>

  <link name="rear_link">
 <inertial>
         <mass value="3.57593" />
         <inertia  ixx="9.10834154273" ixy="1.58213307656"  ixz="2.41894531959"  iyy="7.61461127751"  iyz="3.78869385449"  izz="3.51520282177" />
       </inertial>
    <visual>
      <geometry>
        <box size="0.04 1.5 0.19"/>
      </geometry>
      <material name="white">
        <color rgba="1 1 1 1"/>
      </material>
    </visual>
    <collision>
      <geometry>
        <box size="0.04 1.5 0.19"/>
      </geometry>
    </collision>
  </link>
  <link name="frame_left_link">
<inertial>
         <mass value="9.27558" />
         <inertia  ixx="0.08543320989" ixy="0.00203527346"  ixz="0.00005369318"  iyy="1.73617847697"  iyz="0.00256904615"  izz="1.80153923143" />
       </inertial>
    <visual>
      <geometry>
        <box size="1.31 0.04 0.19"/>
      </geometry>
      <material name="white">
        <color rgba="1 1 1 1"/>
      </material>
    </visual>
    <collision>
      <geometry>
        <box size="1.31 0.04 0.19"/>
      </geometry>
    </collision>
  </link>
  <link name="frame_right_link">
<inertial>
         <mass value="9.27558" />
         <inertia  ixx="0.08543320989" ixy="0.00203527346"  ixz="0.00005369318"  iyy="1.73617847697"  iyz="0.00256904615"  izz="1.80153923143" />
       </inertial>

    <visual>
      <geometry>
        <box size="1.31 0.04 0.19"/>
      </geometry>
      <material name="white">
        <color rgba="1 1 1 1"/>
      </material>
    </visual>
    <collision>
      <geometry>
        <box size="1.31 0.04 0.19"/>
      </geometry>
    </collision>
  </link>
  <link name="left_battery_link">
<inertial>
         <mass value="6.31990" />
         <inertia  ixx="0.29398133956" ixy="-0.00466804851"  ixz="0.01762371158"  iyy="0.34338589741"  iyz="-0.01930502652"  izz="0.36556453481" />
       </inertial>
    <visual>
      <geometry>
        <box size="0.5 0.25 0.4"/>
      </geometry>
      <material name="white">
        <color rgba="1 1 1 1"/>
      </material>
    </visual>
    <collision>
      <geometry>
        <box size="0.5 0.25 0.4"/>
      </geometry>
    </collision>
  </link>
  <link name="right_battery_link">
<inertial>
         <mass value="6.31990" />
         <inertia  ixx="0.29398133956" ixy="-0.00466804851"  ixz="0.01762371158"  iyy="0.34338589741"  iyz="-0.01930502652"  izz="0.36556453481" />
       </inertial>
    <visual>
      <geometry>
        <box size="0.5 0.25 0.4"/>
      </geometry>
      <material name="white">
        <color rgba="1 1 1 1"/>
      </material>
    </visual>
    <collision>
      <geometry>
        <box size="0.5 0.25 0.4"/>
      </geometry>
    </collision>
  </link>
  <link name="sensor_box_link">
<inertial>
         <mass value="6" />
         <inertia  ixx="0.001" ixy="-0.00"  ixz="0.0"  iyy="0.001"  iyz="0.0"  izz="0.001" />
       </inertial>
    <visual>
      <geometry>
        <box size="0.159 0.336 0.27"/>
      </geometry>
      <material name="wood">
        <color rgba="0.6 0.5 0.2 1"/>
      </material>
    </visual>
    <collision>
      <geometry>
        <box size="0.159 0.336 0.27"/>
      </geometry>
    </collision>
  </link>

  <joint name="base_link_front_frame" type="fixed">
    <parent link="base_link"/>
    <child link="front_frame"/>
    <origin xyz="0.6 0 0" rpy="0 0 0"/>
  </joint>
  <joint name="front_frame_front_link" type="fixed">
    <parent link="front_frame"/>
    <child link="front_link"/>
    <origin rpy="0 0 0" xyz="-0.2 0 0"/>
  </joint>
  <joint name="front_rear" type="fixed">
    <parent link="front_link"/>
    <child link="rear_link"/>
    <origin rpy="0 0 0" xyz="-0.91 0 0"/>
  </joint>
  <joint name="frame_front_left" type="fixed">
    <parent link="front_link"/>
    <child link="frame_left_link"/>
    <origin rpy="0 0 0" xyz="-0.455 0.75 0"/>
  </joint>
  <joint name="frame_front_right" type="fixed">
    <parent link="front_link"/>
    <child link="frame_right_link"/>
    <origin rpy="0 0 0" xyz="-0.455 -0.75 0"/>
  </joint>
  <joint name="frame_battery_left" type="fixed">
    <parent link="frame_left_link"/>
    <child link="left_battery_link"/>
    <origin rpy="0 0 0" xyz="0.0 0.05 -0.15"/>
  </joint>
  <joint name="frame_battery_right" type="fixed">
    <parent link="frame_right_link"/>
    <child link="right_battery_link"/>
    <origin rpy="0 0 0" xyz="0.0 -0.05 -0.15"/>
  </joint>
  <joint name="frame_sensor_box" type="fixed">
    <parent link="front_link"/>
    <child link="sensor_box_link"/>
    <origin rpy="0 0 0" xyz="0.1 0.0 0.0"/>
  </joint>
  <link name="rear_right_leg">
<inertial>
         <mass value="18.04113851362" />
         <inertia  ixx="0.42070073921738702" ixy="-0.06822925640195674"  ixz="0.00112608960289035"  iyy="0.14032771307242548"  iyz="0.04164060266313061"  izz="0.37196263174132627" />
       </inertial>
    <visual>
      <geometry>
        <cylinder length="0.495" radius="0.04"/>
      </geometry>
      <material name="white">
        <color rgba="0 0 0"/>
      </material>
    </visual>
    <collision>
      <geometry>
        <cylinder length="0.495" radius="0.04"/>
      </geometry>
    </collision>
  </link>
  <joint name="steering0" type="continuous">
    <parent link="frame_right_link"/>
    <child link="rear_right_leg"/>
    <origin rpy="0 0 0" xyz="-0.655 0 -0.2"/>
    <axis xyz="0 0 1"/>
  </joint>
  <link name="rear_right_wheel">
<inertial>
         <mass value="6.38698" />
         <inertia  ixx="0.41728824734" ixy="-0.00126432781"  ixz="0.00"  iyy="0.09931113387"  iyz="-0.000000002"  izz="0.3547904736" />
       </inertial>
    <visual>
      <geometry>
        <cylinder length="0.16" radius="0.2"/>
      </geometry>
      <material name="black">
        <color rgba="1 1 1"/>
      </material>
    </visual>
    <collision>
      <geometry>
        <cylinder length="0.16" radius="0.2"/>
      </geometry>
    </collision>
  </link>
  <joint name="wheel0" type="continuous">
    <parent link="rear_right_leg"/>
    <child link="rear_right_wheel"/>
    <origin rpy="-1.5707963268 0 0" xyz="0 0 -0.2"/>
    <axis xyz="0 0 1"/>
  </joint>
  <link name="front_right_leg">
<inertial>
         <mass value="18.04113851362" />
         <inertia  ixx="0.42070073921738702" ixy="-0.06822925640195674"  ixz="0.00112608960289035"  iyy="0.14032771307242548"  iyz="0.04164060266313061"  izz="0.37196263174132627" />
       </inertial>
    <visual>
      <geometry>
        <cylinder length="0.495" radius="0.04"/>
      </geometry>
      <material name="white">
        <color rgba="0 0 0"/>
      </material>
    </visual>
    <collision>
      <geometry>
        <cylinder length="0.495" radius="0.04"/>
      </geometry>
    </collision>
  </link>
  <joint name="steering1" type="continuous">
    <parent link="frame_right_link"/>
    <child link="front_right_leg"/>
    <origin rpy="0 0 0" xyz="0.655 0 -0.2"/>
    <axis xyz="0 0 1"/>
  </joint>
  <link name="front_right_wheel">
<inertial>
         <mass value="6.38698" />
         <inertia  ixx="0.41728824734" ixy="-0.00126432781"  ixz="0.00"  iyy="0.09931113387"  iyz="-0.000000002"  izz="0.3547904736" />
       </inertial>
    <visual>
      <geometry>
        <cylinder length="0.16" radius="0.2"/>
      </geometry>
      <material name="black">
        <color rgba="1 1 1"/>
      </material>
    </visual>
    <collision>
      <geometry>
        <cylinder length="0.16" radius="0.2"/>
      </geometry>
    </collision>
  </link>
  <joint name="wheel1" type="continuous">
    <parent link="front_right_leg"/>
    <child link="front_right_wheel"/>
    <origin rpy="-1.5707963268 0 0" xyz="0 0 -0.2"/>
    <axis xyz="0 0 1"/>
  </joint>
  <link name="front_left_leg">
<inertial>
         <mass value="18.04113851362" />
         <inertia  ixx="0.42070073921738702" ixy="-0.06822925640195674"  ixz="0.00112608960289035"  iyy="0.14032771307242548"  iyz="0.04164060266313061"  izz="0.37196263174132627" />
       </inertial>
    <visual>
      <geometry>
        <cylinder length="0.495" radius="0.04"/>
      </geometry>
      <material name="white">
        <color rgba="0 0 0"/>
      </material>
    </visual>
    <collision>
      <geometry>
        <cylinder length="0.495" radius="0.04"/>
      </geometry>
    </collision>
  </link>
  <joint name="steering2" type="continuous">
    <parent link="frame_left_link"/>
    <child link="front_left_leg"/>
    <origin rpy="0 0 0" xyz="0.655 0 -0.2"/>
    <axis xyz="0 0 1"/>
  </joint>
  <link name="front_left_wheel">
<inertial>
         <mass value="6.38698" />
         <inertia  ixx="0.41728824734" ixy="-0.00126432781"  ixz="0.00"  iyy="0.09931113387"  iyz="-0.000000002"  izz="0.3547904736" />
       </inertial>
    <visual>
      <geometry>
        <cylinder length="0.16" radius="0.2"/>
      </geometry>
      <material name="black">
        <color rgba="1 1 1"/>
      </material>
    </visual>
    <collision>
      <geometry>
        <cylinder length="0.16" radius="0.2"/>
      </geometry>
    </collision>
  </link>
  <joint name="wheel2" type="continuous">
    <parent link="front_left_leg"/>
    <child link="front_left_wheel"/>
    <origin rpy="-1.5707963268 0 0" xyz="0 0 -0.2"/>
    <axis xyz="0 0 1"/>
  </joint>
  <link name="rear_left_leg">
<inertial>
         <mass value="18.04113851362" />
         <inertia  ixx="0.42070073921738702" ixy="-0.06822925640195674"  ixz="0.00112608960289035"  iyy="0.14032771307242548"  iyz="0.04164060266313061"  izz="0.37196263174132627" />
       </inertial>
    <visual>
      <geometry>
        <cylinder length="0.495" radius="0.04"/>
      </geometry>
      <material name="white">
        <color rgba="0 0 0"/>
      </material>
    </visual>
    <collision>
      <geometry>
        <cylinder length="0.495" radius="0.04"/>
      </geometry>
    </collision>
  </link>
  <joint name="steering3" type="continuous">
    <parent link="frame_left_link"/>
    <child link="rear_left_leg"/>
    <origin rpy="0 0 0" xyz="-0.655 0 -0.2"/>
    <axis xyz="0 0 1"/>
  </joint>
  <link name="rear_left_wheel">
<inertial>
         <mass value="6.38698" />
         <inertia  ixx="0.41728824734" ixy="-0.00126432781"  ixz="0.00"  iyy="0.09931113387"  iyz="-0.000000002"  izz="0.3547904736" />
       </inertial>
    <visual>
      <geometry>
        <cylinder length="0.16" radius="0.2"/>
      </geometry>
      <material name="black">
        <color rgba="1 1 1"/>
      </material>
    </visual>
    <collision>
      <geometry>
        <cylinder length="0.16" radius="0.2"/>
      </geometry>
    </collision>
  </link>
  <joint name="wheel3" type="continuous">
    <parent link="rear_left_leg"/>
    <child link="rear_left_wheel"/>
    <origin rpy="-1.5707963268 0 0" xyz="0 0 -0.2"/>
    <axis xyz="0 0 1"/>
  </joint>

  <!-- Hokuyo Laser -->
  <link name="laser">
    <collision>
      <origin xyz="0 0 0" rpy="0 0 0"/>
      <geometry>
    <box size="0.1 0.1 0.1"/>
      </geometry>
    </collision>

    <visual>
      <origin xyz="0 0 0" rpy="0 0 0"/>
      <geometry>
        <mesh filename="package://testbot_description/meshes/hokuyo.dae"/>
      </geometry>
    </visual>

    <inertial>
      <mass value="1e-5" />
      <origin xyz="0 0 0" rpy="0 0 0"/>
      <inertia ixx="1e-6" ixy="0" ixz="0" iyy="1e-6" iyz="0" izz="1e-6" />
    </inertial>
  </link>

<joint name="hokuyo_joint" type="fixed">
    <axis xyz="0 1 0" />
    <origin xyz="0.02 0 0.2" rpy="0 0 0"/>
    <parent link="front_link"/>
    <child link="laser"/>
  </joint>


</robot>

